Workbook

Sheet Criteria
A1: Column1 | B1: Cost | C1: Enviromental | D1: Industrial scale | E1: Process complexity | F1: Access to resources | G1: Recycling purity
A2: Cost | B2: Equal Importance | C2: Slightly More Important | D2: Moderately More Important | E2: Strongly Less Important | F2: Strongly Less Important | G2: Strongly More Important
A3: Enviromental | B3: =IF(ISBLANK(OFFSET($B$2, COLUMN()-COLUMN($B$2), ROW()-ROW($B$2))), "", _xlfn.XLOOKUP(OFFSET($B$2, COLUMN()-COLUMN($B$2), ROW()-ROW($B$2)), Sheet7!A2:A8, Sheet7!B2:B8, "")) -> Slightly Less Important | C3: Equal Importance | D3: Equal Importance | E3: Strongly Less Important | F3: Strongly Less Important | G3: Moderately Less Important
A4: Industrial scale | B4: =IF(ISBLANK(OFFSET($B$2, COLUMN()-COLUMN($B$2), ROW()-ROW($B$2))), "", _xlfn.XLOOKUP(OFFSET($B$2, COLUMN()-COLUMN($B$2), ROW()-ROW($B$2)), Sheet7!A2:A8, Sheet7!B2:B8, "")) -> Moderately Less Important | C4: =IF(ISBLANK(OFFSET($B$2, COLUMN()-COLUMN($B$2), ROW()-ROW($B$2))), "", _xlfn.XLOOKUP(OFFSET($B$2, COLUMN()-COLUMN($B$2), ROW()-ROW($B$2)), Sheet7!A2:A8, Sheet7!B2:B8, "")) -> Equal Importance | D4: Equal Importance | E4: Slightly More Important | F4: Moderately More Important | G4: Slightly Less Important
A5: Process complexity | B5: =IF(ISBLANK(OFFSET($B$2, COLUMN()-COLUMN($B$2), ROW()-ROW($B$2))), "", _xlfn.XLOOKUP(OFFSET($B$2, COLUMN()-COLUMN($B$2), ROW()-ROW($B$2)), Sheet7!A2:A8, Sheet7!B2:B8, "")) -> Strongly More Important | C5: =IF(ISBLANK(OFFSET($B$2, COLUMN()-COLUMN($B$2), ROW()-ROW($B$2))), "", _xlfn.XLOOKUP(OFFSET($B$2, COLUMN()-COLUMN($B$2), ROW()-ROW($B$2)), Sheet7!A2:A8, Sheet7!B2:B8, "")) -> Strongly More Important | D5: =IF(ISBLANK(OFFSET($B$2, COLUMN()-COLUMN($B$2), ROW()-ROW($B$2))), "", _xlfn.XLOOKUP(OFFSET($B$2, COLUMN()-COLUMN($B$2), ROW()-ROW($B$2)), Sheet7!A2:A8, Sheet7!B2:B8, "")) -> Slightly Less Important | E5: Equal Importance | F5: Moderately More Important | G5: Strongly More Important
A6: Access to resources | B6: =IF(ISBLANK(OFFSET($B$2, COLUMN()-COLUMN($B$2), ROW()-ROW($B$2))), "", _xlfn.XLOOKUP(OFFSET($B$2, COLUMN()-COLUMN($B$2), ROW()-ROW($B$2)), Sheet7!A2:A8, Sheet7!B2:B8, "")) -> Strongly More Important | C6: =IF(ISBLANK(OFFSET($B$2, COLUMN()-COLUMN($B$2), ROW()-ROW($B$2))), "", _xlfn.XLOOKUP(OFFSET($B$2, COLUMN()-COLUMN($B$2), ROW()-ROW($B$2)), Sheet7!A2:A8, Sheet7!B2:B8, "")) -> Strongly More Important | D6: =IF(ISBLANK(OFFSET($B$2, COLUMN()-COLUMN($B$2), ROW()-ROW($B$2))), "", _xlfn.XLOOKUP(OFFSET($B$2, COLUMN()-COLUMN($B$2), ROW()-ROW($B$2)), Sheet7!A2:A8, Sheet7!B2:B8, "")) -> Moderately Less Important | E6: =IF(ISBLANK(OFFSET($B$2, COLUMN()-COLUMN($B$2), ROW()-ROW($B$2))), "", _xlfn.XLOOKUP(OFFSET($B$2, COLUMN()-COLUMN($B$2), ROW()-ROW($B$2)), Sheet7!A2:A8, Sheet7!B2:B8, "")) -> Moderately Less Important | F6: Equal Importance | G6: Moderately More Important
A7: Recycling purity | B7: =IF(ISBLANK(OFFSET($B$2, COLUMN()-COLUMN($B$2), ROW()-ROW($B$2))), "", _xlfn.XLOOKUP(OFFSET($B$2, COLUMN()-COLUMN($B$2), ROW()-ROW($B$2)), Sheet7!A3:A9, Sheet7!B3:B9, "")) -> Strongly Less Important | C7: =IF(ISBLANK(OFFSET($B$2, COLUMN()-COLUMN($B$2), ROW()-ROW($B$2))), "", _xlfn.XLOOKUP(OFFSET($B$2, COLUMN()-COLUMN($B$2), ROW()-ROW($B$2)), Sheet7!A2:A8, Sheet7!B2:B8, "")) -> Moderately More Important | D7: =IF(ISBLANK(OFFSET($B$2, COLUMN()-COLUMN($B$2), ROW()-ROW($B$2))), "", _xlfn.XLOOKUP(OFFSET($B$2, COLUMN()-COLUMN($B$2), ROW()-ROW($B$2)), Sheet7!A2:A8, Sheet7!B2:B8, "")) -> Slightly More Important | E7: =IF(ISBLANK(OFFSET($B$2, COLUMN()-COLUMN($B$2), ROW()-ROW($B$2))), "", _xlfn.XLOOKUP(OFFSET($B$2, COLUMN()-COLUMN($B$2), ROW()-ROW($B$2)), Sheet7!A2:A8, Sheet7!B2:B8, "")) -> Strongly Less Important | F7: =IF(ISBLANK(OFFSET($B$2, COLUMN()-COLUMN($B$2), ROW()-ROW($B$2))), "", _xlfn.XLOOKUP(OFFSET($B$2, COLUMN()-COLUMN($B$2), ROW()-ROW($B$2)), Sheet7!A2:A8, Sheet7!B2:B8, "")) -> Moderately Less Important | G7: Equal Importance

Sheet Cost
A10: Cost | B10: P1 | C10: P2 | D10: P3 | E10: P4 | F10: P5 | G10: P6 | H10: P7 | I10: P8 | J10: P9 | K10: P10 | L10: P11 | M10: P12 | N10: P13 | O10: P14 | P10: P15 | Q10: P16 | R10: P17 | S10: P18 | T10: P19 | U10: P20 | V10: P21 | W10: P22 | X10: P23 | Y10: P24 | Z10: P25
A11: P1 | B11: Equal Importance | C11: Slightly Less Important | D11: Strongly Less Important | E11: Strongly Less Important | F11: Strongly Less Important | G11: Strongly Less Important | H11: Strongly Less Important | I11: Moderately Less Important | J11: Moderately Less Important | K11: Strongly More Important | L11: Strongly Less Important | M11: Moderately Less Important | N11: Moderately Less Important | O11: Moderately Less Important | P11: Moderately Less Important | Q11: Strongly Less Important | R11: Moderately Less Important | S11: Strongly Less Important | T11: Strongly Less Important | U11: Strongly Less Important | V11: Strongly Less Important | W11: Strongly Less Important | X11: Slightly Less Important | Y11: Slightly More Important | Z11: Strongly Less Important
A12: P2 | B12: =IF(ISBLANK(OFFSET($C$12, COLUMN()-COLUMN($C$12), ROW()-ROW($C$12))), "", _xlfn.XLOOKUP(OFFSET($C$12, COLUMN()-COLUMN($C$12), ROW()-ROW($C$12)), Sheet7!A2:A8, Sheet7!B2:B8, "")) -> Slightly More Important | C12: Equal Importance | D12: Strongly Less Important | E12: Strongly Less Important | F12: Strongly Less Important | G12: Strongly Less Important | H12: Strongly Less Important | I12: Moderately Less Important | J12: Moderately Less Important | K12: Strongly More Important | L12: Strongly Less Important | M12: Moderately Less Important | N12: Moderately Less Important | O12: Moderately Less Important | P12: Moderately Less Important | Q12: Moderately Less Important | R12: Slightly Less Important | S12: Strongly Less Important | T12: Strongly Less Important | U12: Strongly Less Important | V12: Moderately Less Important | W12: Strongly Less Important | X12: Slightly Less Important | Y12: Slightly More Important | Z12: Strongly Less Important
A13: P3 | B13: =IF(ISBLANK(OFFSET($C$12, COLUMN()-COLUMN($C$12), ROW()-ROW($C$12))), "", _xlfn.XLOOKUP(OFFSET($C$12, COLUMN()-COLUMN($C$12), ROW()-ROW($C$12)), Sheet7!A2:A8, Sheet7!B2:B8, "")) -> Strongly More Important | C13: =IF(ISBLANK(OFFSET($C$12, COLUMN()-COLUMN($C$12), ROW()-ROW($C$12))), "", _xlfn.XLOOKUP(OFFSET($C$12, COLUMN()-COLUMN($C$12), ROW()-ROW($C$12)), Sheet7!A2:A8, Sheet7!B2:B8, "")) -> Strongly More Important | D13: Equal Importance | E13: Equal Importance | F13: Equal Importance | G13: Equal Importance | H13: Equal Importance | I13: Moderately More Important | J13: Moderately More Important | K13: Strongly More Important | L13: Slightly More Important | M13: Moderately More Important | N13: Moderately More Important | O13: Moderately More Important | P13: Moderately More Important | Q13: Moderately More Important | R13: Strongly More Important | S13: Slightly More Important | T13: Slightly More Important | U13: Slightly More Important | V13: Moderately More Important | W13: Slightly Less Important | X13: Strongly More Important | Y13: Strongly More Important | Z13: Moderately More Important
A14: P4 | B14: =IF(ISBLANK(OFFSET($C$12, COLUMN()-COLUMN($C$12), ROW()-ROW($C$12))), "", _xlfn.XLOOKUP(OFFSET($C$12, COLUMN()-COLUMN($C$12), ROW()-ROW($C$12)), Sheet7!A2:A8, Sheet7!B2:B8, "")) -> Strongly More Important | C14: =IF(ISBLANK(OFFSET($C$12, COLUMN()-COLUMN($C$12), ROW()-ROW($C$12))), "", _xlfn.XLOOKUP(OFFSET($C$12, COLUMN()-COLUMN($C$12), ROW()-ROW($C$12)), Sheet7!A2:A8, Sheet7!B2:B8, "")) -> Strongly More Important | D14: =IF(ISBLANK(OFFSET($C$12, COLUMN()-COLUMN($C$12), ROW()-ROW($C$12))), "", _xlfn.XLOOKUP(OFFSET($C$12, COLUMN()-COLUMN($C$12), ROW()-ROW($C$12)), Sheet7!A2:A8, Sheet7!B2:B8, "")) -> Equal Importance | E14: Equal Importance | F14: Equal Importance | G14: Equal Importance | H14: Equal Importance | I14: Moderately More Important | J14: Moderately More Important | K14: Strongly More Important | L14: Slightly More Important | M14: Moderately More Important | N14: Moderately More Important | O14: Moderately More Important | P14: Moderately More Important | Q14: Moderately More Important | R14: Strongly More Important | S14: Slightly More Important | T14: Slightly More Important | U14: Slightly More Important | V14: Moderately More Important | W14: Slightly Less Important | X14: Strongly More Important | Y14: Strongly More Important | Z14: Moderately More Important
A15: P5 | B15: =IF(ISBLANK(OFFSET($C$12, COLUMN()-COLUMN($C$12), ROW()-ROW($C$12))), "", _xlfn.XLOOKUP(OFFSET($C$12, COLUMN()-COLUMN($C$12), ROW()-ROW($C$12)), Sheet7!A2:A8, Sheet7!B2:B8, "")) -> Strongly More Important | C15: =IF(ISBLANK(OFFSET($C$12, COLUMN()-COLUMN($C$12), ROW()-ROW($C$12))), "", _xlfn.XLOOKUP(OFFSET($C$12, COLUMN()-COLUMN($C$12), ROW()-ROW($C$12)), Sheet7!A2:A8, Sheet7!B2:B8, "")) -> Strongly More Important | D15: =IF(ISBLANK(OFFSET($C$12, COLUMN()-COLUMN($C$12), ROW()-ROW($C$12))), "", _xlfn.XLOOKUP(OFFSET($C$12, COLUMN()-COLUMN($C$12), ROW()-ROW($C$12)), Sheet7!A2:A8, Sheet7!B2:B8, "")) -> Equal Importance | E15: =IF(ISBLANK(OFFSET($C$12, COLUMN()-COLUMN($C$12), ROW()-ROW($C$12))), "", _xlfn.XLOOKUP(OFFSET($C$12, COLUMN()-COLUMN($C$12), ROW()-ROW($C$12)), Sheet7!A2:A8, Sheet7!B2:B8, "")) -> Equal Importance | F15: Equal Importance | G15: Equal Importance | H15: Equal Importance | I15: Moderately More Important | J15: Moderately More Important | K15: Strongly More Important | L15: Slightly More Important | M15: Moderately More Important | N15: Moderately More Important | O15: Moderately More Important | P15: Moderately More Important | Q15: Moderately More Important | R15: Strongly More Important | S15: Slightly More Important | T15: Slightly More Important | U15: Slightly More Important | V15: Moderately More Important | W15: Slightly Less Important | X15: Strongly More Important | Y15: Strongly More Important | Z15: Moderately More Important
A16: P6 | B16: =IF(ISBLANK(OFFSET($C$12, COLUMN()-COLUMN($C$12), ROW()-ROW($C$12))), "", _xlfn.XLOOKUP(OFFSET($C$12, COLUMN()-COLUMN($C$12), ROW()-ROW($C$12)), Sheet7!A2:A8, Sheet7!B2:B8, "")) -> Strongly More Important | C16: =IF(ISBLANK(OFFSET($C$12, COLUMN()-COLUMN($C$12), ROW()-ROW($C$12))), "", _xlfn.XLOOKUP(OFFSET($C$12, COLUMN()-COLUMN($C$12), ROW()-ROW($C$12)), Sheet7!A2:A8, Sheet7!B2:B8, "")) -> Strongly More Important | D16: =IF(ISBLANK(OFFSET($C$12, COLUMN()-COLUMN($C$12), ROW()-ROW($C$12))), "", _xlfn.XLOOKUP(OFFSET($C$12, COLUMN()-COLUMN($C$12), ROW()-ROW($C$12)), Sheet7!A2:A8, Sheet7!B2:B8, "")) -> Equal Importance | E16: =IF(ISBLANK(OFFSET($C$12, COLUMN()-COLUMN($C$12), ROW()-ROW($C$12))), "", _xlfn.XLOOKUP(OFFSET($C$12, COLUMN()-COLUMN($C$12), ROW()-ROW($C$12)), Sheet7!A2:A8, Sheet7!B2:B8, "")) -> Equal Importance | F16: =IF(ISBLANK(OFFSET($C$12, COLUMN()-COLUMN($C$12), ROW()-ROW($C$12))), "", _xlfn.XLOOKUP(OFFSET($C$12, COLUMN()-COLUMN($C$12), ROW()-ROW($C$12)), Sheet7!A2:A8, Sheet7!B2:B8, "")) -> Equal Importance | G16: Equal Importance | H16: Equal Importance | I16: Moderately More Important | J16: Moderately More Important | K16: Strongly More Important | L16: Slightly More Important | M16: Moderately More Important | N16: Moderately More Important | O16: Moderately More Important | P16: Moderately More Important | Q16: Moderately More Important | R16: Strongly More Important | S16: Slightly More Important | T16: Slightly More Important | U16: Slightly More Important | V16: Moderately More Important | W16: Slightly Less Important | X16: Strongly More Important | Y16: Strongly More Important | Z16: Moderately More Important
A17: P7 | B17: =IF(ISBLANK(OFFSET($C$12, COLUMN()-COLUMN($C$12), ROW()-ROW($C$12))), "", _xlfn.XLOOKUP(OFFSET($C$12, COLUMN()-COLUMN($C$12), ROW()-ROW($C$12)), Sheet7!A2:A8, Sheet7!B2:B8, "")) -> Strongly More Important | C17: =IF(ISBLANK(OFFSET($C$12, COLUMN()-COLUMN($C$12), ROW()-ROW($C$12))), "", _xlfn.XLOOKUP(OFFSET($C$12, COLUMN()-COLUMN($C$12), ROW()-ROW($C$12)), Sheet7!A2:A8, Sheet7!B2:B8, "")) -> Strongly More Important | D17: =IF(ISBLANK(OFFSET($C$12, COLUMN()-COLUMN($C$12), ROW()-ROW($C$12))), "", _xlfn.XLOOKUP(OFFSET($C$12, COLUMN()-COLUMN($C$12), ROW()-ROW($C$12)), Sheet7!A2:A8, Sheet7!B2:B8, "")) -> Equal Importance | E17: =IF(ISBLANK(OFFSET($C$12, COLUMN()-COLUMN($C$12), ROW()-ROW($C$12))), "", _xlfn.XLOOKUP(OFFSET($C$12, COLUMN()-COLUMN($C$12), ROW()-ROW($C$12)), Sheet7!A2:A8, Sheet7!B2:B8, "")) -> Equal Importance | F17: =IF(ISBLANK(OFFSET($C$12, COLUMN()-COLUMN($C$12), ROW()-ROW($C$12))), "", _xlfn.XLOOKUP(OFFSET($C$12, COLUMN()-COLUMN($C$12), ROW()-ROW($C$12)), Sheet7!A2:A8, Sheet7!B2:B8, "")) -> Equal Importance | G17: =IF(ISBLANK(OFFSET($C$12, COLUMN()-COLUMN($C$12), ROW()-ROW($C$12))), "", _xlfn.XLOOKUP(OFFSET($C$12, COLUMN()-COLUMN($C$12), ROW()-ROW($C$12)), Sheet7!A2:A8, Sheet7!B2:B8, "")) -> Equal Importance | H17: Equal Importance | I17: Moderately More Important | J17: Moderately More Important | K17: Strongly More Important | L17: Slightly More Important | M17: Moderately More Important | N17: Moderately More Important | O17: Moderately More Important | P17: Moderately More Important | Q17: Moderately More Important | R17: Strongly More Important | S17: Slightly More Important | T17: Slightly More Important | U17: Slightly More Important | V17: Moderately More Important | W17: Slightly Less Important | X17: Strongly More Important | Y17: Strongly More Important | Z17: Moderately More Important
A18: P8 | B18: =IF(ISBLANK(OFFSET($C$12, COLUMN()-COLUMN($C$12), ROW()-ROW($C$12))), "", _xlfn.XLOOKUP(OFFSET($C$12, COLUMN()-COLUMN($C$12), ROW()-ROW($C$12)), Sheet7!A2:A8, Sheet7!B2:B8, "")) -> Moderately More Important | C18: =IF(ISBLANK(OFFSET($C$12, COLUMN()-COLUMN($C$12), ROW()-ROW($C$12))), "", _xlfn.XLOOKUP(OFFSET($C$12, COLUMN()-COLUMN($C$12), ROW()-ROW($C$12)), Sheet7!A2:A8, Sheet7!B2:B8, "")) -> Moderately More Important | D18: =IF(ISBLANK(OFFSET($C$12, COLUMN()-COLUMN($C$12), ROW()-ROW($C$12))), "", _xlfn.XLOOKUP(OFFSET($C$12, COLUMN()-COLUMN($C$12), ROW()-ROW($C$12)), Sheet7!A2:A8, Sheet7!B2:B8, "")) -> Moderately Less Important | E18: =IF(ISBLANK(OFFSET($C$12, COLUMN()-COLUMN($C$12), ROW()-ROW($C$12))), "", _xlfn.XLOOKUP(OFFSET($C$12, COLUMN()-COLUMN($C$12), ROW()-ROW($C$12)), Sheet7!A2:A8, Sheet7!B2:B8, "")) -> Moderately Less Important | F18: =IF(ISBLANK(OFFSET($C$12, COLUMN()-COLUMN($C$12), ROW()-ROW($C$12))), "", _xlfn.XLOOKUP(OFFSET($C$12, COLUMN()-COLUMN($C$12), ROW()-ROW($C$12)), Sheet7!A2:A8, Sheet7!B2:B8, "")) -> Moderately Less Important | G18: =IF(ISBLANK(OFFSET($C$12, COLUMN()-COLUMN($C$12), ROW()-ROW($C$12))), "", _xlfn.XLOOKUP(OFFSET($C$12, COLUMN()-COLUMN($C$12), ROW()-ROW($C$12)), Sheet7!A2:A8, Sheet7!B2:B8, "")) -> Moderately Less Important | H18: =IF(ISBLANK(OFFSET($C$12, COLUMN()-COLUMN($C$12), ROW()-ROW($C$12))), "", _xlfn.XLOOKUP(OFFSET($C$12, COLUMN()-COLUMN($C$12), ROW()-ROW($C$12)), Sheet7!A2:A8, Sheet7!B2:B8, "")) -> Moderately Less Important | I18: Equal Importance | J18: Equal Importance | K18: Strongly More Important | L18: Slightly Less Important | M18: Slightly More Important | N18: Slightly More Important | O18: Slightly More Important | P18: Slightly More Important | Q18: Slightly More Important | R18: Moderately More Important | S18: Moderately Less Important | T18: Moderately Less Important | U18: Moderately Less Important | V18: Slightly Less Important | W18: Moderately Less Important | X18: Moderately More Important | Y18: Moderately More Important | Z18: Slightly Less Important
A19: P9 | B19: =IF(ISBLANK(OFFSET($C$12, COLUMN()-COLUMN($C$12), ROW()-ROW($C$12))), "", _xlfn.XLOOKUP(OFFSET($C$12, COLUMN()-COLUMN($C$12), ROW()-ROW($C$12)), Sheet7!A2:A8, Sheet7!B2:B8, "")) -> Moderately More Important | C19: =IF(ISBLANK(OFFSET($C$12, COLUMN()-COLUMN($C$12), ROW()-ROW($C$12))), "", _xlfn.XLOOKUP(OFFSET($C$12, COLUMN()-COLUMN($C$12), ROW()-ROW($C$12)), Sheet7!A2:A8, Sheet7!B2:B8, "")) -> Moderately More Important | D19: =IF(ISBLANK(OFFSET($C$12, COLUMN()-COLUMN($C$12), ROW()-ROW($C$12))), "", _xlfn.XLOOKUP(OFFSET($C$12, COLUMN()-COLUMN($C$12), ROW()-ROW($C$12)), Sheet7!A2:A8, Sheet7!B2:B8, "")) -> Moderately Less Important | E19: =IF(ISBLANK(OFFSET($C$12, COLUMN()-COLUMN($C$12), ROW()-ROW($C$12))), "", _xlfn.XLOOKUP(OFFSET($C$12, COLUMN()-COLUMN($C$12), ROW()-ROW($C$12)), Sheet7!A2:A8, Sheet7!B2:B8, "")) -> Moderately Less Important | F19: =IF(ISBLANK(OFFSET($C$12, COLUMN()-COLUMN($C$12), ROW()-ROW($C$12))), "", _xlfn.XLOOKUP(OFFSET($C$12, COLUMN()-COLUMN($C$12), ROW()-ROW($C$12)), Sheet7!A2:A8, Sheet7!B2:B8, "")) -> Moderately Less Important | G19: =IF(ISBLANK(OFFSET($C$12, COLUMN()-COLUMN($C$12), ROW()-ROW($C$12))), "", _xlfn.XLOOKUP(OFFSET($C$12, COLUMN()-COLUMN($C$12), ROW()-ROW($C$12)), Sheet7!A2:A8, Sheet7!B2:B8, "")) -> Moderately Less Important | H19: =IF(ISBLANK(OFFSET($C$12, COLUMN()-COLUMN($C$12), ROW()-ROW($C$12))), "", _xlfn.XLOOKUP(OFFSET($C$12, COLUMN()-COLUMN($C$12), ROW()-ROW($C$12)), Sheet7!A2:A8, Sheet7!B2:B8, "")) -> Moderately Less Important | I19: =IF(ISBLANK(OFFSET($C$12, COLUMN()-COLUMN($C$12), ROW()-ROW($C$12))), "", _xlfn.XLOOKUP(OFFSET($C$12, COLUMN()-COLUMN($C$12), ROW()-ROW($C$12)), Sheet7!A2:A8, Sheet7!B2:B8, "")) -> Equal Importance | J19: Equal Importance | K19: Strongly More Important | L19: Slightly Less Important | M19: Slightly More Important | N19: Slightly More Important | O19: Slightly More Important | P19: Slightly More Important | Q19: Slightly More Important | R19: Moderately More Important | S19: Moderately Less Important | T19: Moderately Less Important | U19: Moderately Less Important | V19: Slightly Less Important | W19: Moderately Less Important | X19: Moderately More Important | Y19: Moderately More Important | Z19: Slightly Less Important
A20: P10 | B20: =IF(ISBLANK(OFFSET($C$12, COLUMN()-COLUMN($C$12), ROW()-ROW($C$12))), "", _xlfn.XLOOKUP(OFFSET($C$12, COLUMN()-COLUMN($C$12), ROW()-ROW($C$12)), Sheet7!A2:A8, Sheet7!B2:B8, "")) -> Strongly Less Important | C20: =IF(ISBLANK(OFFSET($C$12, COLUMN()-COLUMN($C$12), ROW()-ROW($C$12))), "", _xlfn.XLOOKUP(OFFSET($C$12, COLUMN()-COLUMN($C$12), ROW()-ROW($C$12)), Sheet7!A2:A8, Sheet7!B2:B8, "")) -> Strongly Less Important | D20: =IF(ISBLANK(OFFSET($C$12, COLUMN()-COLUMN($C$12), ROW()-ROW($C$12))), "", _xlfn.XLOOKUP(OFFSET($C$12, COLUMN()-COLUMN($C$12), ROW()-ROW($C$12)), Sheet7!A2:A8, Sheet7!B2:B8, "")) -> Strongly Less Important | E20: =IF(ISBLANK(OFFSET($C$12, COLUMN()-COLUMN($C$12), ROW()-ROW($C$12))), "", _xlfn.XLOOKUP(OFFSET($C$12, COLUMN()-COLUMN($C$12), ROW()-ROW($C$12)), Sheet7!A2:A8, Sheet7!B2:B8, "")) -> Strongly Less Important | F20: =IF(ISBLANK(OFFSET($C$12, COLUMN()-COLUMN($C$12), ROW()-ROW($C$12))), "", _xlfn.XLOOKUP(OFFSET($C$12, COLUMN()-COLUMN($C$12), ROW()-ROW($C$12)), Sheet7!A2:A8, Sheet7!B2:B8, "")) -> Strongly Less Important | G20: =IF(ISBLANK(OFFSET($C$12, COLUMN()-COLUMN($C$12), ROW()-ROW($C$12))), "", _xlfn.XLOOKUP(OFFSET($C$12, COLUMN()-COLUMN($C$12), ROW()-ROW($C$12)), Sheet7!A2:A8, Sheet7!B2:B8, "")) -> Strongly Less Important | H20: =IF(ISBLANK(OFFSET($C$12, COLUMN()-COLUMN($C$12), ROW()-ROW($C$12))), "", _xlfn.XLOOKUP(OFFSET($C$12, COLUMN()-COLUMN($C$12), ROW()-ROW($C$12)), Sheet7!A2:A8, Sheet7!B2:B8, "")) -> Strongly Less Important | I20: =IF(ISBLANK(OFFSET($C$12, COLUMN()-COLUMN($C$12), ROW()-ROW($C$12))), "", _xlfn.XLOOKUP(OFFSET($C$12, COLUMN()-COLUMN($C$12), ROW()-ROW($C$12)), Sheet7!A2:A8, Sheet7!B2:B8, "")) -> Strongly Less Important | J20: =IF(ISBLANK(OFFSET($C$12, COLUMN()-COLUMN($C$12), ROW()-ROW($C$12))), "", _xlfn.XLOOKUP(OFFSET($C$12, COLUMN()-COLUMN($C$12), ROW()-ROW($C$12)), Sheet7!A2:A8, Sheet7!B2:B8, "")) -> Strongly Less Important | K20: Equal Importance | L20: Strongly Less Important | M20: Strongly Less Important | N20: Strongly Less Important | O20: Strongly Less Important | P20: Strongly Less Important | Q20: Strongly Less Important | R20: Strongly Less Important | S20: Strongly Less Important | T20: Strongly Less Important | U20: Strongly Less Important | V20: Strongly Less Important | W20: Strongly Less Important | X20: Strongly Less Important | Y20: Slightly Less Important | Z20: Strongly Less Important
A21: P11 | B21: =IF(ISBLANK(OFFSET($C$12, COLUMN()-COLUMN($C$12), ROW()-ROW($C$12))), "", _xlfn.XLOOKUP(OFFSET($C$12, COLUMN()-COLUMN($C$12), ROW()-ROW($C$12)), Sheet7!A2:A8, Sheet7!B2:B8, "")) -> Strongly More Important | C21: =IF(ISBLANK(OFFSET($C$12, COLUMN()-COLUMN($C$12), ROW()-ROW($C$12))), "", _xlfn.XLOOKUP(OFFSET($C$12, COLUMN()-COLUMN($C$12), ROW()-ROW($C$12)), Sheet7!A2:A8, Sheet7!B2:B8, "")) -> Strongly More Important | D21: =IF(ISBLANK(OFFSET($C$12, COLUMN()-COLUMN($C$12), ROW()-ROW($C$12))), "", _xlfn.XLOOKUP(OFFSET($C$12, COLUMN()-COLUMN($C$12), ROW()-ROW($C$12)), Sheet7!A2:A8, Sheet7!B2:B8, "")) -> Slightly Less Important | E21: =IF(ISBLANK(OFFSET($C$12, COLUMN()-COLUMN($C$12), ROW()-ROW($C$12))), "", _xlfn.XLOOKUP(OFFSET($C$12, COLUMN()-COLUMN($C$12), ROW()-ROW($C$12)), Sheet7!A2:A8, Sheet7!B2:B8, "")) -> Slightly Less Important | F21: =IF(ISBLANK(OFFSET($C$12, COLUMN()-COLUMN($C$12), ROW()-ROW($C$12))), "", _xlfn.XLOOKUP(OFFSET($C$12, COLUMN()-COLUMN($C$12), ROW()-ROW($C$12)), Sheet7!A2:A8, Sheet7!B2:B8, "")) -> Slightly Less Important | G21: =IF(ISBLANK(OFFSET($C$12, COLUMN()-COLUMN($C$12), ROW()-ROW($C$12))), "", _xlfn.XLOOKUP(OFFSET($C$12, COLUMN()-COLUMN($C$12), ROW()-ROW($C$12)), Sheet7!A2:A8, Sheet7!B2:B8, "")) -> Slightly Less Important | H21: =IF(ISBLANK(OFFSET($C$12, COLUMN()-COLUMN($C$12), ROW()-ROW($C$12))), "", _xlfn.XLOOKUP(OFFSET($C$12, COLUMN()-COLUMN($C$12), ROW()-ROW($C$12)), Sheet7!A2:A8, Sheet7!B2:B8, "")) -> Slightly Less Important | I21: =IF(ISBLANK(OFFSET($C$12, COLUMN()-COLUMN($C$12), ROW()-ROW($C$12))), "", _xlfn.XLOOKUP(OFFSET($C$12, COLUMN()-COLUMN($C$12), ROW()-ROW($C$12)), Sheet7!A2:A8, Sheet7!B2:B8, "")) -> Slightly More Important | J21: =IF(ISBLANK(OFFSET($C$12, COLUMN()-COLUMN($C$12), ROW()-ROW($C$12))), "", _xlfn.XLOOKUP(OFFSET($C$12, COLUMN()-COLUMN($C$12), ROW()-ROW($C$12)), Sheet7!A2:A8, Sheet7!B2:B8, "")) -> Slightly More Important | K21: =IF(ISBLANK(OFFSET($C$12, COLUMN()-COLUMN($C$12), ROW()-ROW($C$12))), "", _xlfn.XLOOKUP(OFFSET($C$12, COLUMN()-COLUMN($C$12), ROW()-ROW($C$12)), Sheet7!A2:A8, Sheet7!B2:B8, "")) -> Strongly More Important | L21: Equal Importance | M21: Moderately More Important | N21: Moderately More Important | O21: Moderately More Important | P21: Moderately More Important | Q21: Moderately More Important | R21: Moderately More Important | S21: Slightly Less Important | T21: Slightly Less Important | U21: Slightly Less Important | V21: Slightly More Important | W21: Moderately Less Important | X21: Strongly More Important | Y21: Strongly More Important | Z21: Slightly More Important
A22: P12 | B22: =IF(ISBLANK(OFFSET($C$12, COLUMN()-COLUMN($C$12), ROW()-ROW($C$12))), "", _xlfn.XLOOKUP(OFFSET($C$12, COLUMN()-COLUMN($C$12), ROW()-ROW($C$12)), Sheet7!A2:A8, Sheet7!B2:B8, "")) -> Moderately More Important | C22: =IF(ISBLANK(OFFSET($C$12, COLUMN()-COLUMN($C$12), ROW()-ROW($C$12))), "", _xlfn.XLOOKUP(OFFSET($C$12, COLUMN()-COLUMN($C$12), ROW()-ROW($C$12)), Sheet7!A2:A8, Sheet7!B2:B8, "")) -> Moderately More Important | D22: =IF(ISBLANK(OFFSET($C$12, COLUMN()-COLUMN($C$12), ROW()-ROW($C$12))), "", _xlfn.XLOOKUP(OFFSET($C$12, COLUMN()-COLUMN($C$12), ROW()-ROW($C$12)), Sheet7!A2:A8, Sheet7!B2:B8, "")) -> Moderately Less Important | E22: =IF(ISBLANK(OFFSET($C$12, COLUMN()-COLUMN($C$12), ROW()-ROW($C$12))), "", _xlfn.XLOOKUP(OFFSET($C$12, COLUMN()-COLUMN($C$12), ROW()-ROW($C$12)), Sheet7!A2:A8, Sheet7!B2:B8, "")) -> Moderately Less Important | F22: =IF(ISBLANK(OFFSET($C$12, COLUMN()-COLUMN($C$12), ROW()-ROW($C$12))), "", _xlfn.XLOOKUP(OFFSET($C$12, COLUMN()-COLUMN($C$12), ROW()-ROW($C$12)), Sheet7!A2:A8, Sheet7!B2:B8, "")) -> Moderately Less Important | G22: =IF(ISBLANK(OFFSET($C$12, COLUMN()-COLUMN($C$12), ROW()-ROW($C$12))), "", _xlfn.XLOOKUP(OFFSET($C$12, COLUMN()-COLUMN($C$12), ROW()-ROW($C$12)), Sheet7!A2:A8, Sheet7!B2:B8, "")) -> Moderately Less Important | H22: =IF(ISBLANK(OFFSET($C$12, COLUMN()-COLUMN($C$12), ROW()-ROW($C$12))), "", _xlfn.XLOOKUP(OFFSET($C$12, COLUMN()-COLUMN($C$12), ROW()-ROW($C$12)), Sheet7!A2:A8, Sheet7!B2:B8, "")) -> Moderately Less Important | I22: =IF(ISBLANK(OFFSET($C$12, COLUMN()-COLUMN($C$12), ROW()-ROW($C$12))), "", _xlfn.XLOOKUP(OFFSET($C$12, COLUMN()-COLUMN($C$12), ROW()-ROW($C$12)), Sheet7!A2:A8, Sheet7!B2:B8, "")) -> Slightly Less Important | J22: =IF(ISBLANK(OFFSET($C$12, COLUMN()-COLUMN($C$12), ROW()-ROW($C$12))), "", _xlfn.XLOOKUP(OFFSET($C$12, COLUMN()-COLUMN($C$12), ROW()-ROW($C$12)), Sheet7!A2:A8, Sheet7!B2:B8, "")) -> Slightly Less Important | K22: =IF(ISBLANK(OFFSET($C$12, COLUMN()-COLUMN($C$12), ROW()-ROW($C$12))), "", _xlfn.XLOOKUP(OFFSET($C$12, COLUMN()-COLUMN($C$12), ROW()-ROW($C$12)), Sheet7!A2:A8, Sheet7!B2:B8, "")) -> Strongly More Important | L22: =IF(ISBLANK(OFFSET($C$12, COLUMN()-COLUMN($C$12), ROW()-ROW($C$12))), "", _xlfn.XLOOKUP(OFFSET($C$12, COLUMN()-COLUMN($C$12), ROW()-ROW($C$12)), Sheet7!$A$2:$A$8, Sheet7!$B$2:$B$8, "")) -> Moderately Less Important | M22: Equal Importance | N22: Equal Importance | O22: Equal Importance | P22: Equal Importance | Q22: Slightly Less Important | R22: Slightly More Important | S22: Moderately Less Important | T22: Moderately Less Important | U22: Moderately Less Important | V22: Moderately Less Important | W22: Strongly Less Important | X22: Slightly More Important | Y22: Moderately More Important | Z22: Moderately More Important
A23: P13 | B23: =IF(ISBLANK(OFFSET($C$12, COLUMN()-COLUMN($C$12), ROW()-ROW($C$12))), "", _xlfn.XLOOKUP(OFFSET($C$12, COLUMN()-COLUMN($C$12), ROW()-ROW($C$12)), Sheet7!A2:A8, Sheet7!B2:B8, "")) -> Moderately More Important | C23: =IF(ISBLANK(OFFSET($C$12, COLUMN()-COLUMN($C$12), ROW()-ROW($C$12))), "", _xlfn.XLOOKUP(OFFSET($C$12, COLUMN()-COLUMN($C$12), ROW()-ROW($C$12)), Sheet7!A2:A8, Sheet7!B2:B8, "")) -> Moderately More Important | D23: =IF(ISBLANK(OFFSET($C$12, COLUMN()-COLUMN($C$12), ROW()-ROW($C$12))), "", _xlfn.XLOOKUP(OFFSET($C$12, COLUMN()-COLUMN($C$12), ROW()-ROW($C$12)), Sheet7!A2:A8, Sheet7!B2:B8, "")) -> Moderately Less Important | E23: =IF(ISBLANK(OFFSET($C$12, COLUMN()-COLUMN($C$12), ROW()-ROW($C$12))), "", _xlfn.XLOOKUP(OFFSET($C$12, COLUMN()-COLUMN($C$12), ROW()-ROW($C$12)), Sheet7!A2:A8, Sheet7!B2:B8, "")) -> Moderately Less Important | F23: =IF(ISBLANK(OFFSET($C$12, COLUMN()-COLUMN($C$12), ROW()-ROW($C$12))), "", _xlfn.XLOOKUP(OFFSET($C$12, COLUMN()-COLUMN($C$12), ROW()-ROW($C$12)), Sheet7!A2:A8, Sheet7!B2:B8, "")) -> Moderately Less Important | G23: =IF(ISBLANK(OFFSET($C$12, COLUMN()-COLUMN($C$12), ROW()-ROW($C$12))), "", _xlfn.XLOOKUP(OFFSET($C$12, COLUMN()-COLUMN($C$12), ROW()-ROW($C$12)), Sheet7!A2:A8, Sheet7!B2:B8, "")) -> Moderately Less Important | H23: =IF(ISBLANK(OFFSET($C$12, COLUMN()-COLUMN($C$12), ROW()-ROW($C$12))), "", _xlfn.XLOOKUP(OFFSET($C$12, COLUMN()-COLUMN($C$12), ROW()-ROW($C$12)), Sheet7!A2:A8, Sheet7!B2:B8, "")) -> Moderately Less Important | I23: =IF(ISBLANK(OFFSET($C$12, COLUMN()-COLUMN($C$12), ROW()-ROW($C$12))), "", _xlfn.XLOOKUP(OFFSET($C$12, COLUMN()-COLUMN($C$12), ROW()-ROW($C$12)), Sheet7!A2:A8, Sheet7!B2:B8, "")) -> Slightly Less Important | J23: =IF(ISBLANK(OFFSET($C$12, COLUMN()-COLUMN($C$12), ROW()-ROW($C$12))), "", _xlfn.XLOOKUP(OFFSET($C$12, COLUMN()-COLUMN($C$12), ROW()-ROW($C$12)), Sheet7!A2:A8, Sheet7!B2:B8, "")) -> Slightly Less Important | K23: =IF(ISBLANK(OFFSET($C$12, COLUMN()-COLUMN($C$12), ROW()-ROW($C$12))), "", _xlfn.XLOOKUP(OFFSET($C$12, COLUMN()-COLUMN($C$12), ROW()-ROW($C$12)), Sheet7!A2:A8, Sheet7!B2:B8, "")) -> Strongly More Important | L23: =IF(ISBLANK(OFFSET($C$12, COLUMN()-COLUMN($C$12), ROW()-ROW($C$12))), "", _xlfn.XLOOKUP(OFFSET($C$12, COLUMN()-COLUMN($C$12), ROW()-ROW($C$12)), Sheet7!$A$2:$A$8, Sheet7!$B$2:$B$8, "")) -> Moderately Less Important | M23: =IF(ISBLANK(OFFSET($C$12, COLUMN()-COLUMN($C$12), ROW()-ROW($C$12))), "", _xlfn.XLOOKUP(OFFSET($C$12, COLUMN()-COLUMN($C$12), ROW()-ROW($C$12)), Sheet7!$A$2:$A$8, Sheet7!$B$2:$B$8, "")) -> Equal Importance | N23: Equal Importance | O23: Equal Importance | P23: Equal Importance | Q23: Slightly Less Important | R23: Slightly More Important | S23: Moderately Less Important | T23: Moderately Less Important | U23: Moderately Less Important | V23: Moderately Less Important | W23: Strongly Less Important | X23: Slightly More Important | Y23: Moderately More Important | Z23: Moderately More Important
A24: P14 | B24: =IF(ISBLANK(OFFSET($C$12, COLUMN()-COLUMN($C$12), ROW()-ROW($C$12))), "", _xlfn.XLOOKUP(OFFSET($C$12, COLUMN()-COLUMN($C$12), ROW()-ROW($C$12)), Sheet7!A2:A8, Sheet7!B2:B8, "")) -> Moderately More Important | C24: =IF(ISBLANK(OFFSET($C$12, COLUMN()-COLUMN($C$12), ROW()-ROW($C$12))), "", _xlfn.XLOOKUP(OFFSET($C$12, COLUMN()-COLUMN($C$12), ROW()-ROW($C$12)), Sheet7!A2:A8, Sheet7!B2:B8, "")) -> Moderately More Important | D24: =IF(ISBLANK(OFFSET($C$12, COLUMN()-COLUMN($C$12), ROW()-ROW($C$12))), "", _xlfn.XLOOKUP(OFFSET($C$12, COLUMN()-COLUMN($C$12), ROW()-ROW($C$12)), Sheet7!A2:A8, Sheet7!B2:B8, "")) -> Moderately Less Important | E24: =IF(ISBLANK(OFFSET($C$12, COLUMN()-COLUMN($C$12), ROW()-ROW($C$12))), "", _xlfn.XLOOKUP(OFFSET($C$12, COLUMN()-COLUMN($C$12), ROW()-ROW($C$12)), Sheet7!A2:A8, Sheet7!B2:B8, "")) -> Moderately Less Important | F24: =IF(ISBLANK(OFFSET($C$12, COLUMN()-COLUMN($C$12), ROW()-ROW($C$12))), "", _xlfn.XLOOKUP(OFFSET($C$12, COLUMN()-COLUMN($C$12), ROW()-ROW($C$12)), Sheet7!A2:A8, Sheet7!B2:B8, "")) -> Moderately Less Important | G24: =IF(ISBLANK(OFFSET($C$12, COLUMN()-COLUMN($C$12), ROW()-ROW($C$12))), "", _xlfn.XLOOKUP(OFFSET($C$12, COLUMN()-COLUMN($C$12), ROW()-ROW($C$12)), Sheet7!A2:A8, Sheet7!B2:B8, "")) -> Moderately Less Important | H24: =IF(ISBLANK(OFFSET($C$12, COLUMN()-COLUMN($C$12), ROW()-ROW($C$12))), "", _xlfn.XLOOKUP(OFFSET($C$12, COLUMN()-COLUMN($C$12), ROW()-ROW($C$12)), Sheet7!A2:A8, Sheet7!B2:B8, "")) -> Moderately Less Important | I24: =IF(ISBLANK(OFFSET($C$12, COLUMN()-COLUMN($C$12), ROW()-ROW($C$12))), "", _xlfn.XLOOKUP(OFFSET($C$12, COLUMN()-COLUMN($C$12), ROW()-ROW($C$12)), Sheet7!A2:A8, Sheet7!B2:B8, "")) -> Slightly Less Important | J24: =IF(ISBLANK(OFFSET($C$12, COLUMN()-COLUMN($C$12), ROW()-ROW($C$12))), "", _xlfn.XLOOKUP(OFFSET($C$12, COLUMN()-COLUMN($C$12), ROW()-ROW($C$12)), Sheet7!A2:A8, Sheet7!B2:B8, "")) -> Slightly Less Important | K24: =IF(ISBLANK(OFFSET($C$12, COLUMN()-COLUMN($C$12), ROW()-ROW($C$12))), "", _xlfn.XLOOKUP(OFFSET($C$12, COLUMN()-COLUMN($C$12), ROW()-ROW($C$12)), Sheet7!A2:A8, Sheet7!B2:B8, "")) -> Strongly More Important | L24: =IF(ISBLANK(OFFSET($C$12, COLUMN()-COLUMN($C$12), ROW()-ROW($C$12))), "", _xlfn.XLOOKUP(OFFSET($C$12, COLUMN()-COLUMN($C$12), ROW()-ROW($C$12)), Sheet7!$A$2:$A$8, Sheet7!$B$2:$B$8, "")) -> Moderately Less Important | M24: =IF(ISBLANK(OFFSET($C$12, COLUMN()-COLUMN($C$12), ROW()-ROW($C$12))), "", _xlfn.XLOOKUP(OFFSET($C$12, COLUMN()-COLUMN($C$12), ROW()-ROW($C$12)), Sheet7!$A$2:$A$8, Sheet7!$B$2:$B$8, "")) -> Equal Importance | N24: =IF(ISBLANK(OFFSET($C$12, COLUMN()-COLUMN($C$12), ROW()-ROW($C$12))), "", _xlfn.XLOOKUP(OFFSET($C$12, COLUMN()-COLUMN($C$12), ROW()-ROW($C$12)), Sheet7!$A$2:$A$8, Sheet7!$B$2:$B$8, "")) -> Equal Importance | O24: Equal Importance | P24: Equal Importance | Q24: Slightly Less Important | R24: Slightly More Important | S24: Moderately Less Important | T24: Moderately Less Important | U24: Moderately Less Important | V24: Moderately Less Important | W24: Strongly Less Important | X24: Slightly More Important | Y24: Moderately More Important | Z24: Moderately More Important
A25: P15 | B25: =IF(ISBLANK(OFFSET($C$12, COLUMN()-COLUMN($C$12), ROW()-ROW($C$12))), "", _xlfn.XLOOKUP(OFFSET($C$12, COLUMN()-COLUMN($C$12), ROW()-ROW($C$12)), Sheet7!A2:A8, Sheet7!B2:B8, "")) -> Moderately More Important | C25: =IF(ISBLANK(OFFSET($C$12, COLUMN()-COLUMN($C$12), ROW()-ROW($C$12))), "", _xlfn.XLOOKUP(OFFSET($C$12, COLUMN()-COLUMN($C$12), ROW()-ROW($C$12)), Sheet7!A2:A8, Sheet7!B2:B8, "")) -> Moderately More Important | D25: =IF(ISBLANK(OFFSET($C$12, COLUMN()-COLUMN($C$12), ROW()-ROW($C$12))), "", _xlfn.XLOOKUP(OFFSET($C$12, COLUMN()-COLUMN($C$12), ROW()-ROW($C$12)), Sheet7!A2:A8, Sheet7!B2:B8, "")) -> Moderately Less Important | E25: =IF(ISBLANK(OFFSET($C$12, COLUMN()-COLUMN($C$12), ROW()-ROW($C$12))), "", _xlfn.XLOOKUP(OFFSET($C$12, COLUMN()-COLUMN($C$12), ROW()-ROW($C$12)), Sheet7!A2:A8, Sheet7!B2:B8, "")) -> Moderately Less Important | F25: =IF(ISBLANK(OFFSET($C$12, COLUMN()-COLUMN($C$12), ROW()-ROW($C$12))), "", _xlfn.XLOOKUP(OFFSET($C$12, COLUMN()-COLUMN($C$12), ROW()-ROW($C$12)), Sheet7!A2:A8, Sheet7!B2:B8, "")) -> Moderately Less Important | G25: =IF(ISBLANK(OFFSET($C$12, COLUMN()-COLUMN($C$12), ROW()-ROW($C$12))), "", _xlfn.XLOOKUP(OFFSET($C$12, COLUMN()-COLUMN($C$12), ROW()-ROW($C$12)), Sheet7!A2:A8, Sheet7!B2:B8, "")) -> Moderately Less Important | H25: =IF(ISBLANK(OFFSET($C$12, COLUMN()-COLUMN($C$12), ROW()-ROW($C$12))), "", _xlfn.XLOOKUP(OFFSET($C$12, COLUMN()-COLUMN($C$12), ROW()-ROW($C$12)), Sheet7!A2:A8, Sheet7!B2:B8, "")) -> Moderately Less Important | I25: =IF(ISBLANK(OFFSET($C$12, COLUMN()-COLUMN($C$12), ROW()-ROW($C$12))), "", _xlfn.XLOOKUP(OFFSET($C$12, COLUMN()-COLUMN($C$12), ROW()-ROW($C$12)), Sheet7!A2:A8, Sheet7!B2:B8, "")) -> Slightly Less Important | J25: =IF(ISBLANK(OFFSET($C$12, COLUMN()-COLUMN($C$12), ROW()-ROW($C$12))), "", _xlfn.XLOOKUP(OFFSET($C$12, COLUMN()-COLUMN($C$12), ROW()-ROW($C$12)), Sheet7!A2:A8, Sheet7!B2:B8, "")) -> Slightly Less Important | K25: =IF(ISBLANK(OFFSET($C$12, COLUMN()-COLUMN($C$12), ROW()-ROW($C$12))), "", _xlfn.XLOOKUP(OFFSET($C$12, COLUMN()-COLUMN($C$12), ROW()-ROW($C$12)), Sheet7!$A$2:$A$8, Sheet7!$B$2:$B$8, "")) -> Strongly More Important | L25: =IF(ISBLANK(OFFSET($C$12, COLUMN()-COLUMN($C$12), ROW()-ROW($C$12))), "", _xlfn.XLOOKUP(OFFSET($C$12, COLUMN()-COLUMN($C$12), ROW()-ROW($C$12)), Sheet7!$A$2:$A$8, Sheet7!$B$2:$B$8, "")) -> Moderately Less Important | M25: =IF(ISBLANK(OFFSET($C$12, COLUMN()-COLUMN($C$12), ROW()-ROW($C$12))), "", _xlfn.XLOOKUP(OFFSET($C$12, COLUMN()-COLUMN($C$12), ROW()-ROW($C$12)), Sheet7!$A$2:$A$8, Sheet7!$B$2:$B$8, "")) -> Equal Importance | N25: =IF(ISBLANK(OFFSET($C$12, COLUMN()-COLUMN($C$12), ROW()-ROW($C$12))), "", _xlfn.XLOOKUP(OFFSET($C$12, COLUMN()-COLUMN($C$12), ROW()-ROW($C$12)), Sheet7!$A$2:$A$8, Sheet7!$B$2:$B$8, "")) -> Equal Importance | O25: =IF(ISBLANK(OFFSET($C$12, COLUMN()-COLUMN($C$12), ROW()-ROW($C$12))), "", _xlfn.XLOOKUP(OFFSET($C$12, COLUMN()-COLUMN($C$12), ROW()-ROW($C$12)), Sheet7!$A$2:$A$8, Sheet7!$B$2:$B$8, "")) -> Equal Importance | P25: Equal Importance | Q25: Slightly Less Important | R25: Slightly More Important | S25: Moderately Less Important | T25: Moderately Less Important | U25: Moderately Less Important | V25: Moderately Less Important | W25: Strongly Less Important | X25: Slightly More Important | Y25: Moderately More Important | Z25: Moderately More Important
A26: P16 | B26: =IF(ISBLANK(OFFSET($C$12, COLUMN()-COLUMN($C$12), ROW()-ROW($C$12))), "", _xlfn.XLOOKUP(OFFSET($C$12, COLUMN()-COLUMN($C$12), ROW()-ROW($C$12)), Sheet7!A2:A8, Sheet7!B2:B8, "")) -> Strongly More Important | C26: =IF(ISBLANK(OFFSET($C$12, COLUMN()-COLUMN($C$12), ROW()-ROW($C$12))), "", _xlfn.XLOOKUP(OFFSET($C$12, COLUMN()-COLUMN($C$12), ROW()-ROW($C$12)), Sheet7!A2:A8, Sheet7!B2:B8, "")) -> Moderately More Important | D26: =IF(ISBLANK(OFFSET($C$12, COLUMN()-COLUMN($C$12), ROW()-ROW($C$12))), "", _xlfn.XLOOKUP(OFFSET($C$12, COLUMN()-COLUMN($C$12), ROW()-ROW($C$12)), Sheet7!A2:A8, Sheet7!B2:B8, "")) -> Moderately Less Important | E26: =IF(ISBLANK(OFFSET($C$12, COLUMN()-COLUMN($C$12), ROW()-ROW($C$12))), "", _xlfn.XLOOKUP(OFFSET($C$12, COLUMN()-COLUMN($C$12), ROW()-ROW($C$12)), Sheet7!A2:A8, Sheet7!B2:B8, "")) -> Moderately Less Important | F26: =IF(ISBLANK(OFFSET($C$12, COLUMN()-COLUMN($C$12), ROW()-ROW($C$12))), "", _xlfn.XLOOKUP(OFFSET($C$12, COLUMN()-COLUMN($C$12), ROW()-ROW($C$12)), Sheet7!A2:A8, Sheet7!B2:B8, "")) -> Moderately Less Important | G26: =IF(ISBLANK(OFFSET($C$12, COLUMN()-COLUMN($C$12), ROW()-ROW($C$12))), "", _xlfn.XLOOKUP(OFFSET($C$12, COLUMN()-COLUMN($C$12), ROW()-ROW($C$12)), Sheet7!A2:A8, Sheet7!B2:B8, "")) -> Moderately Less Important | H26: =IF(ISBLANK(OFFSET($C$12, COLUMN()-COLUMN($C$12), ROW()-ROW($C$12))), "", _xlfn.XLOOKUP(OFFSET($C$12, COLUMN()-COLUMN($C$12), ROW()-ROW($C$12)), Sheet7!A2:A8, Sheet7!B2:B8, "")) -> Moderately Less Important | I26: =IF(ISBLANK(OFFSET($C$12, COLUMN()-COLUMN($C$12), ROW()-ROW($C$12))), "", _xlfn.XLOOKUP(OFFSET($C$12, COLUMN()-COLUMN($C$12), ROW()-ROW($C$12)), Sheet7!A2:A8, Sheet7!B2:B8, "")) -> Slightly Less Important | J26: =IF(ISBLANK(OFFSET($C$12, COLUMN()-COLUMN($C$12), ROW()-ROW($C$12))), "", _xlfn.XLOOKUP(OFFSET($C$12, COLUMN()-COLUMN($C$12), ROW()-ROW($C$12)), Sheet7!A2:A8, Sheet7!B2:B8, "")) -> Slightly Less Important | K26: =IF(ISBLANK(OFFSET($C$12, COLUMN()-COLUMN($C$12), ROW()-ROW($C$12))), "", _xlfn.XLOOKUP(OFFSET($C$12, COLUMN()-COLUMN($C$12), ROW()-ROW($C$12)), Sheet7!A2:A8, Sheet7!B2:B8, "")) -> Strongly More Important | L26: =IF(ISBLANK(OFFSET($C$12, COLUMN()-COLUMN($C$12), ROW()-ROW($C$12))), "", _xlfn.XLOOKUP(OFFSET($C$12, COLUMN()-COLUMN($C$12), ROW()-ROW($C$12)), Sheet7!$A$2:$A$8, Sheet7!$B$2:$B$8, "")) -> Moderately Less Important | M26: =IF(ISBLANK(OFFSET($C$12, COLUMN()-COLUMN($C$12), ROW()-ROW($C$12))), "", _xlfn.XLOOKUP(OFFSET($C$12, COLUMN()-COLUMN($C$12), ROW()-ROW($C$12)), Sheet7!$A$2:$A$8, Sheet7!$B$2:$B$8, "")) -> Slightly More Important | N26: =IF(ISBLANK(OFFSET($C$12, COLUMN()-COLUMN($C$12), ROW()-ROW($C$12))), "", _xlfn.XLOOKUP(OFFSET($C$12, COLUMN()-COLUMN($C$12), ROW()-ROW($C$12)), Sheet7!$A$2:$A$8, Sheet7!$B$2:$B$8, "")) -> Slightly More Important | O26: =IF(ISBLANK(OFFSET($C$12, COLUMN()-COLUMN($C$12), ROW()-ROW($C$12))), "", _xlfn.XLOOKUP(OFFSET($C$12, COLUMN()-COLUMN($C$12), ROW()-ROW($C$12)), Sheet7!$A$2:$A$8, Sheet7!$B$2:$B$8, "")) -> Slightly More Important | P26: =IF(ISBLANK(OFFSET($C$12, COLUMN()-COLUMN($C$12), ROW()-ROW($C$12))), "", _xlfn.XLOOKUP(OFFSET($C$12, COLUMN()-COLUMN($C$12), ROW()-ROW($C$12)), Sheet7!$A$2:$A$8, Sheet7!$B$2:$B$8, "")) -> Slightly More Important | Q26: Equal Importance | R26: Moderately More Important | S26: Moderately Less Important | T26: Moderately Less Important | U26: Moderately Less Important | V26: Slightly More Important | W26: Strongly Less Important | X26: Moderately More Important | Y26: Strongly More Important | Z26: Moderately Less Important
A27: P17 | B27: =IF(ISBLANK(OFFSET($C$12, COLUMN()-COLUMN($C$12), ROW()-ROW($C$12))), "", _xlfn.XLOOKUP(OFFSET($C$12, COLUMN()-COLUMN($C$12), ROW()-ROW($C$12)), Sheet7!A2:A8, Sheet7!B2:B8, "")) -> Moderately More Important | C27: =IF(ISBLANK(OFFSET($C$12, COLUMN()-COLUMN($C$12), ROW()-ROW($C$12))), "", _xlfn.XLOOKUP(OFFSET($C$12, COLUMN()-COLUMN($C$12), ROW()-ROW($C$12)), Sheet7!A2:A8, Sheet7!B2:B8, "")) -> Slightly More Important | D27: =IF(ISBLANK(OFFSET($C$12, COLUMN()-COLUMN($C$12), ROW()-ROW($C$12))), "", _xlfn.XLOOKUP(OFFSET($C$12, COLUMN()-COLUMN($C$12), ROW()-ROW($C$12)), Sheet7!A2:A8, Sheet7!B2:B8, "")) -> Strongly Less Important | E27: =IF(ISBLANK(OFFSET($C$12, COLUMN()-COLUMN($C$12), ROW()-ROW($C$12))), "", _xlfn.XLOOKUP(OFFSET($C$12, COLUMN()-COLUMN($C$12), ROW()-ROW($C$12)), Sheet7!A2:A8, Sheet7!B2:B8, "")) -> Strongly Less Important | F27: =IF(ISBLANK(OFFSET($C$12, COLUMN()-COLUMN($C$12), ROW()-ROW($C$12))), "", _xlfn.XLOOKUP(OFFSET($C$12, COLUMN()-COLUMN($C$12), ROW()-ROW($C$12)), Sheet7!A2:A8, Sheet7!B2:B8, "")) -> Strongly Less Important | G27: =IF(ISBLANK(OFFSET($C$12, COLUMN()-COLUMN($C$12), ROW()-ROW($C$12))), "", _xlfn.XLOOKUP(OFFSET($C$12, COLUMN()-COLUMN($C$12), ROW()-ROW($C$12)), Sheet7!A2:A8, Sheet7!B2:B8, "")) -> Strongly Less Important | H27: =IF(ISBLANK(OFFSET($C$12, COLUMN()-COLUMN($C$12), ROW()-ROW($C$12))), "", _xlfn.XLOOKUP(OFFSET($C$12, COLUMN()-COLUMN($C$12), ROW()-ROW($C$12)), Sheet7!A2:A8, Sheet7!B2:B8, "")) -> Strongly Less Important | I27: =IF(ISBLANK(OFFSET($C$12, COLUMN()-COLUMN($C$12), ROW()-ROW($C$12))), "", _xlfn.XLOOKUP(OFFSET($C$12, COLUMN()-COLUMN($C$12), ROW()-ROW($C$12)), Sheet7!A2:A8, Sheet7!B2:B8, "")) -> Moderately Less Important | J27: =IF(ISBLANK(OFFSET($C$12, COLUMN()-COLUMN($C$12), ROW()-ROW($C$12))), "", _xlfn.XLOOKUP(OFFSET($C$12, COLUMN()-COLUMN($C$12), ROW()-ROW($C$12)), Sheet7!A2:A8, Sheet7!B2:B8, "")) -> Moderately Less Important | K27: =IF(ISBLANK(OFFSET($C$12, COLUMN()-COLUMN($C$12), ROW()-ROW($C$12))), "", _xlfn.XLOOKUP(OFFSET($C$12, COLUMN()-COLUMN($C$12), ROW()-ROW($C$12)), Sheet7!A2:A8, Sheet7!B2:B8, "")) -> Strongly More Important | L27: =IF(ISBLANK(OFFSET($C$12, COLUMN()-COLUMN($C$12), ROW()-ROW($C$12))), "", _xlfn.XLOOKUP(OFFSET($C$12, COLUMN()-COLUMN($C$12), ROW()-ROW($C$12)), Sheet7!$A$2:$A$8, Sheet7!$B$2:$B$8, "")) -> Moderately Less Important | M27: =IF(ISBLANK(OFFSET($C$12, COLUMN()-COLUMN($C$12), ROW()-ROW($C$12))), "", _xlfn.XLOOKUP(OFFSET($C$12, COLUMN()-COLUMN($C$12), ROW()-ROW($C$12)), Sheet7!$A$2:$A$8, Sheet7!$B$2:$B$8, "")) -> Slightly Less Important | N27: =IF(ISBLANK(OFFSET($C$12, COLUMN()-COLUMN($C$12), ROW()-ROW($C$12))), "", _xlfn.XLOOKUP(OFFSET($C$12, COLUMN()-COLUMN($C$12), ROW()-ROW($C$12)), Sheet7!$A$2:$A$8, Sheet7!$B$2:$B$8, "")) -> Slightly Less Important | O27: =IF(ISBLANK(OFFSET($C$12, COLUMN()-COLUMN($C$12), ROW()-ROW($C$12))), "", _xlfn.XLOOKUP(OFFSET($C$12, COLUMN()-COLUMN($C$12), ROW()-ROW($C$12)), Sheet7!$A$2:$A$8, Sheet7!$B$2:$B$8, "")) -> Slightly Less Important | P27: =IF(ISBLANK(OFFSET($C$12, COLUMN()-COLUMN($C$12), ROW()-ROW($C$12))), "", _xlfn.XLOOKUP(OFFSET($C$12, COLUMN()-COLUMN($C$12), ROW()-ROW($C$12)), Sheet7!$A$2:$A$8, Sheet7!$B$2:$B$8, "")) -> Slightly Less Important | Q27: =IF(ISBLANK(OFFSET($C$12, COLUMN()-COLUMN($C$12), ROW()-ROW($C$12))), "", _xlfn.XLOOKUP(OFFSET($C$12, COLUMN()-COLUMN($C$12), ROW()-ROW($C$12)), Sheet7!$A$2:$A$8, Sheet7!$B$2:$B$8, "")) -> Moderately Less Important | R27: Equal Importance | S27: Strongly Less Important | T27: Strongly Less Important | U27: Strongly Less Important | V27: Moderately Less Important | W27: Strongly Less Important | X27: Slightly More Important | Y27: Moderately More Important | Z27: Strongly Less Important
A28: P18 | B28: =IF(ISBLANK(OFFSET($C$12, COLUMN()-COLUMN($C$12), ROW()-ROW($C$12))), "", _xlfn.XLOOKUP(OFFSET($C$12, COLUMN()-COLUMN($C$12), ROW()-ROW($C$12)), Sheet7!A2:A8, Sheet7!B2:B8, "")) -> Strongly More Important | C28: =IF(ISBLANK(OFFSET($C$12, COLUMN()-COLUMN($C$12), ROW()-ROW($C$12))), "", _xlfn.XLOOKUP(OFFSET($C$12, COLUMN()-COLUMN($C$12), ROW()-ROW($C$12)), Sheet7!A2:A8, Sheet7!B2:B8, "")) -> Strongly More Important | D28: =IF(ISBLANK(OFFSET($C$12, COLUMN()-COLUMN($C$12), ROW()-ROW($C$12))), "", _xlfn.XLOOKUP(OFFSET($C$12, COLUMN()-COLUMN($C$12), ROW()-ROW($C$12)), Sheet7!A2:A8, Sheet7!B2:B8, "")) -> Slightly Less Important | E28: =IF(ISBLANK(OFFSET($C$12, COLUMN()-COLUMN($C$12), ROW()-ROW($C$12))), "", _xlfn.XLOOKUP(OFFSET($C$12, COLUMN()-COLUMN($C$12), ROW()-ROW($C$12)), Sheet7!A2:A8, Sheet7!B2:B8, "")) -> Slightly Less Important | F28: =IF(ISBLANK(OFFSET($C$12, COLUMN()-COLUMN($C$12), ROW()-ROW($C$12))), "", _xlfn.XLOOKUP(OFFSET($C$12, COLUMN()-COLUMN($C$12), ROW()-ROW($C$12)), Sheet7!A2:A8, Sheet7!B2:B8, "")) -> Slightly Less Important | G28: =IF(ISBLANK(OFFSET($C$12, COLUMN()-COLUMN($C$12), ROW()-ROW($C$12))), "", _xlfn.XLOOKUP(OFFSET($C$12, COLUMN()-COLUMN($C$12), ROW()-ROW($C$12)), Sheet7!A2:A8, Sheet7!B2:B8, "")) -> Slightly Less Important | H28: =IF(ISBLANK(OFFSET($C$12, COLUMN()-COLUMN($C$12), ROW()-ROW($C$12))), "", _xlfn.XLOOKUP(OFFSET($C$12, COLUMN()-COLUMN($C$12), ROW()-ROW($C$12)), Sheet7!A2:A8, Sheet7!B2:B8, "")) -> Slightly Less Important | I28: =IF(ISBLANK(OFFSET($C$12, COLUMN()-COLUMN($C$12), ROW()-ROW($C$12))), "", _xlfn.XLOOKUP(OFFSET($C$12, COLUMN()-COLUMN($C$12), ROW()-ROW($C$12)), Sheet7!A2:A8, Sheet7!B2:B8, "")) -> Moderately More Important | J28: =IF(ISBLANK(OFFSET($C$12, COLUMN()-COLUMN($C$12), ROW()-ROW($C$12))), "", _xlfn.XLOOKUP(OFFSET($C$12, COLUMN()-COLUMN($C$12), ROW()-ROW($C$12)), Sheet7!A2:A8, Sheet7!B2:B8, "")) -> Moderately More Important | K28: =IF(ISBLANK(OFFSET($C$12, COLUMN()-COLUMN($C$12), ROW()-ROW($C$12))), "", _xlfn.XLOOKUP(OFFSET($C$12, COLUMN()-COLUMN($C$12), ROW()-ROW($C$12)), Sheet7!A2:A8, Sheet7!B2:B8, "")) -> Strongly More Important | L28: =IF(ISBLANK(OFFSET($C$12, COLUMN()-COLUMN($C$12), ROW()-ROW($C$12))), "", _xlfn.XLOOKUP(OFFSET($C$12, COLUMN()-COLUMN($C$12), ROW()-ROW($C$12)), Sheet7!$A$2:$A$8, Sheet7!$B$2:$B$8, "")) -> Slightly More Important | M28: =IF(ISBLANK(OFFSET($C$12, COLUMN()-COLUMN($C$12), ROW()-ROW($C$12))), "", _xlfn.XLOOKUP(OFFSET($C$12, COLUMN()-COLUMN($C$12), ROW()-ROW($C$12)), Sheet7!$A$2:$A$8, Sheet7!$B$2:$B$8, "")) -> Moderately More Important | N28: =IF(ISBLANK(OFFSET($C$12, COLUMN()-COLUMN($C$12), ROW()-ROW($C$12))), "", _xlfn.XLOOKUP(OFFSET($C$12, COLUMN()-COLUMN($C$12), ROW()-ROW($C$12)), Sheet7!$A$2:$A$8, Sheet7!$B$2:$B$8, "")) -> Moderately More Important | O28: =IF(ISBLANK(OFFSET($C$12, COLUMN()-COLUMN($C$12), ROW()-ROW($C$12))), "", _xlfn.XLOOKUP(OFFSET($C$12, COLUMN()-COLUMN($C$12), ROW()-ROW($C$12)), Sheet7!$A$2:$A$8, Sheet7!$B$2:$B$8, "")) -> Moderately More Important | P28: =IF(ISBLANK(OFFSET($C$12, COLUMN()-COLUMN($C$12), ROW()-ROW($C$12))), "", _xlfn.XLOOKUP(OFFSET($C$12, COLUMN()-COLUMN($C$12), ROW()-ROW($C$12)), Sheet7!$A$2:$A$8, Sheet7!$B$2:$B$8, "")) -> Moderately More Important | Q28: =IF(ISBLANK(OFFSET($C$12, COLUMN()-COLUMN($C$12), ROW()-ROW($C$12))), "", _xlfn.XLOOKUP(OFFSET($C$12, COLUMN()-COLUMN($C$12), ROW()-ROW($C$12)), Sheet7!$A$2:$A$8, Sheet7!$B$2:$B$8, "")) -> Moderately More Important | R28: =IF(ISBLANK(OFFSET($C$12, COLUMN()-COLUMN($C$12), ROW()-ROW($C$12))), "", _xlfn.XLOOKUP(OFFSET($C$12, COLUMN()-COLUMN($C$12), ROW()-ROW($C$12)), Sheet7!$A$2:$A$8, Sheet7!$B$2:$B$8, "")) -> Strongly More Important | S28: Equal Importance | T28: Equal Importance | U28: Equal Importance | V28: Moderately More Important | W28: Slightly Less Important | X28: Strongly More Important | Y28: Strongly More Important | Z28: Slightly More Important
A29: P19 | B29: =IF(ISBLANK(OFFSET($C$12, COLUMN()-COLUMN($C$12), ROW()-ROW($C$12))), "", _xlfn.XLOOKUP(OFFSET($C$12, COLUMN()-COLUMN($C$12), ROW()-ROW($C$12)), Sheet7!A2:A8, Sheet7!B2:B8, "")) -> Strongly More Important | C29: =IF(ISBLANK(OFFSET($C$12, COLUMN()-COLUMN($C$12), ROW()-ROW($C$12))), "", _xlfn.XLOOKUP(OFFSET($C$12, COLUMN()-COLUMN($C$12), ROW()-ROW($C$12)), Sheet7!A2:A8, Sheet7!B2:B8, "")) -> Strongly More Important | D29: =IF(ISBLANK(OFFSET($C$12, COLUMN()-COLUMN($C$12), ROW()-ROW($C$12))), "", _xlfn.XLOOKUP(OFFSET($C$12, COLUMN()-COLUMN($C$12), ROW()-ROW($C$12)), Sheet7!A2:A8, Sheet7!B2:B8, "")) -> Slightly Less Important | E29: =IF(ISBLANK(OFFSET($C$12, COLUMN()-COLUMN($C$12), ROW()-ROW($C$12))), "", _xlfn.XLOOKUP(OFFSET($C$12, COLUMN()-COLUMN($C$12), ROW()-ROW($C$12)), Sheet7!A2:A8, Sheet7!B2:B8, "")) -> Slightly Less Important | F29: =IF(ISBLANK(OFFSET($C$12, COLUMN()-COLUMN($C$12), ROW()-ROW($C$12))), "", _xlfn.XLOOKUP(OFFSET($C$12, COLUMN()-COLUMN($C$12), ROW()-ROW($C$12)), Sheet7!A2:A8, Sheet7!B2:B8, "")) -> Slightly Less Important | G29: =IF(ISBLANK(OFFSET($C$12, COLUMN()-COLUMN($C$12), ROW()-ROW($C$12))), "", _xlfn.XLOOKUP(OFFSET($C$12, COLUMN()-COLUMN($C$12), ROW()-ROW($C$12)), Sheet7!A2:A8, Sheet7!B2:B8, "")) -> Slightly Less Important | H29: =IF(ISBLANK(OFFSET($C$12, COLUMN()-COLUMN($C$12), ROW()-ROW($C$12))), "", _xlfn.XLOOKUP(OFFSET($C$12, COLUMN()-COLUMN($C$12), ROW()-ROW($C$12)), Sheet7!A2:A8, Sheet7!B2:B8, "")) -> Slightly Less Important | I29: =IF(ISBLANK(OFFSET($C$12, COLUMN()-COLUMN($C$12), ROW()-ROW($C$12))), "", _xlfn.XLOOKUP(OFFSET($C$12, COLUMN()-COLUMN($C$12), ROW()-ROW($C$12)), Sheet7!A2:A8, Sheet7!B2:B8, "")) -> Moderately More Important | J29: =IF(ISBLANK(OFFSET($C$12, COLUMN()-COLUMN($C$12), ROW()-ROW($C$12))), "", _xlfn.XLOOKUP(OFFSET($C$12, COLUMN()-COLUMN($C$12), ROW()-ROW($C$12)), Sheet7!A2:A8, Sheet7!B2:B8, "")) -> Moderately More Important | K29: =IF(ISBLANK(OFFSET($C$12, COLUMN()-COLUMN($C$12), ROW()-ROW($C$12))), "", _xlfn.XLOOKUP(OFFSET($C$12, COLUMN()-COLUMN($C$12), ROW()-ROW($C$12)), Sheet7!A2:A8, Sheet7!B2:B8, "")) -> Strongly More Important | L29: =IF(ISBLANK(OFFSET($C$12, COLUMN()-COLUMN($C$12), ROW()-ROW($C$12))), "", _xlfn.XLOOKUP(OFFSET($C$12, COLUMN()-COLUMN($C$12), ROW()-ROW($C$12)), Sheet7!$A$2:$A$8, Sheet7!$B$2:$B$8, "")) -> Slightly More Important | M29: =IF(ISBLANK(OFFSET($C$12, COLUMN()-COLUMN($C$12), ROW()-ROW($C$12))), "", _xlfn.XLOOKUP(OFFSET($C$12, COLUMN()-COLUMN($C$12), ROW()-ROW($C$12)), Sheet7!$A$2:$A$8, Sheet7!$B$2:$B$8, "")) -> Moderately More Important | N29: =IF(ISBLANK(OFFSET($C$12, COLUMN()-COLUMN($C$12), ROW()-ROW($C$12))), "", _xlfn.XLOOKUP(OFFSET($C$12, COLUMN()-COLUMN($C$12), ROW()-ROW($C$12)), Sheet7!$A$2:$A$8, Sheet7!$B$2:$B$8, "")) -> Moderately More Important | O29: =IF(ISBLANK(OFFSET($C$12, COLUMN()-COLUMN($C$12), ROW()-ROW($C$12))), "", _xlfn.XLOOKUP(OFFSET($C$12, COLUMN()-COLUMN($C$12), ROW()-ROW($C$12)), Sheet7!$A$2:$A$8, Sheet7!$B$2:$B$8, "")) -> Moderately More Important | P29: =IF(ISBLANK(OFFSET($C$12, COLUMN()-COLUMN($C$12), ROW()-ROW($C$12))), "", _xlfn.XLOOKUP(OFFSET($C$12, COLUMN()-COLUMN($C$12), ROW()-ROW($C$12)), Sheet7!$A$2:$A$8, Sheet7!$B$2:$B$8, "")) -> Moderately More Important | Q29: =IF(ISBLANK(OFFSET($C$12, COLUMN()-COLUMN($C$12), ROW()-ROW($C$12))), "", _xlfn.XLOOKUP(OFFSET($C$12, COLUMN()-COLUMN($C$12), ROW()-ROW($C$12)), Sheet7!$A$2:$A$8, Sheet7!$B$2:$B$8, "")) -> Moderately More Important | R29: =IF(ISBLANK(OFFSET($C$12, COLUMN()-COLUMN($C$12), ROW()-ROW($C$12))), "", _xlfn.XLOOKUP(OFFSET($C$12, COLUMN()-COLUMN($C$12), ROW()-ROW($C$12)), Sheet7!$A$2:$A$8, Sheet7!$B$2:$B$8, "")) -> Strongly More Important | S29: =IF(ISBLANK(OFFSET($C$12, COLUMN()-COLUMN($C$12), ROW()-ROW($C$12))), "", _xlfn.XLOOKUP(OFFSET($C$12, COLUMN()-COLUMN($C$12), ROW()-ROW($C$12)), Sheet7!$A$2:$A$8, Sheet7!$B$2:$B$8, "")) -> Equal Importance | T29: Equal Importance | U29: Equal Importance | V29: Moderately More Important | W29: Slightly Less Important | X29: Strongly More Important | Y29: Strongly More Important | Z29: Slightly More Important
A30: P20 | B30: =IF(ISBLANK(OFFSET($C$12, COLUMN()-COLUMN($C$12), ROW()-ROW($C$12))), "", _xlfn.XLOOKUP(OFFSET($C$12, COLUMN()-COLUMN($C$12), ROW()-ROW($C$12)), Sheet7!A2:A8, Sheet7!B2:B8, "")) -> Strongly More Important | C30: =IF(ISBLANK(OFFSET($C$12, COLUMN()-COLUMN($C$12), ROW()-ROW($C$12))), "", _xlfn.XLOOKUP(OFFSET($C$12, COLUMN()-COLUMN($C$12), ROW()-ROW($C$12)), Sheet7!A2:A8, Sheet7!B2:B8, "")) -> Strongly More Important | D30: =IF(ISBLANK(OFFSET($C$12, COLUMN()-COLUMN($C$12), ROW()-ROW($C$12))), "", _xlfn.XLOOKUP(OFFSET($C$12, COLUMN()-COLUMN($C$12), ROW()-ROW($C$12)), Sheet7!A2:A8, Sheet7!B2:B8, "")) -> Slightly Less Important | E30: =IF(ISBLANK(OFFSET($C$12, COLUMN()-COLUMN($C$12), ROW()-ROW($C$12))), "", _xlfn.XLOOKUP(OFFSET($C$12, COLUMN()-COLUMN($C$12), ROW()-ROW($C$12)), Sheet7!A2:A8, Sheet7!B2:B8, "")) -> Slightly Less Important | F30: =IF(ISBLANK(OFFSET($C$12, COLUMN()-COLUMN($C$12), ROW()-ROW($C$12))), "", _xlfn.XLOOKUP(OFFSET($C$12, COLUMN()-COLUMN($C$12), ROW()-ROW($C$12)), Sheet7!A2:A8, Sheet7!B2:B8, "")) -> Slightly Less Important | G30: =IF(ISBLANK(OFFSET($C$12, COLUMN()-COLUMN($C$12), ROW()-ROW($C$12))), "", _xlfn.XLOOKUP(OFFSET($C$12, COLUMN()-COLUMN($C$12), ROW()-ROW($C$12)), Sheet7!A2:A8, Sheet7!B2:B8, "")) -> Slightly Less Important | H30: =IF(ISBLANK(OFFSET($C$12, COLUMN()-COLUMN($C$12), ROW()-ROW($C$12))), "", _xlfn.XLOOKUP(OFFSET($C$12, COLUMN()-COLUMN($C$12), ROW()-ROW($C$12)), Sheet7!A2:A8, Sheet7!B2:B8, "")) -> Slightly Less Important | I30: =IF(ISBLANK(OFFSET($C$12, COLUMN()-COLUMN($C$12), ROW()-ROW($C$12))), "", _xlfn.XLOOKUP(OFFSET($C$12, COLUMN()-COLUMN($C$12), ROW()-ROW($C$12)), Sheet7!A2:A8, Sheet7!B2:B8, "")) -> Moderately More Important | J30: =IF(ISBLANK(OFFSET($C$12, COLUMN()-COLUMN($C$12), ROW()-ROW($C$12))), "", _xlfn.XLOOKUP(OFFSET($C$12, COLUMN()-COLUMN($C$12), ROW()-ROW($C$12)), Sheet7!A2:A8, Sheet7!B2:B8, "")) -> Moderately More Important | K30: =IF(ISBLANK(OFFSET($C$12, COLUMN()-COLUMN($C$12), ROW()-ROW($C$12))), "", _xlfn.XLOOKUP(OFFSET($C$12, COLUMN()-COLUMN($C$12), ROW()-ROW($C$12)), Sheet7!A2:A8, Sheet7!B2:B8, "")) -> Strongly More Important | L30: =IF(ISBLANK(OFFSET($C$12, COLUMN()-COLUMN($C$12), ROW()-ROW($C$12))), "", _xlfn.XLOOKUP(OFFSET($C$12, COLUMN()-COLUMN($C$12), ROW()-ROW($C$12)), Sheet7!$A$2:$A$8, Sheet7!$B$2:$B$8, "")) -> Slightly More Important | M30: =IF(ISBLANK(OFFSET($C$12, COLUMN()-COLUMN($C$12), ROW()-ROW($C$12))), "", _xlfn.XLOOKUP(OFFSET($C$12, COLUMN()-COLUMN($C$12), ROW()-ROW($C$12)), Sheet7!$A$2:$A$8, Sheet7!$B$2:$B$8, "")) -> Moderately More Important | N30: =IF(ISBLANK(OFFSET($C$12, COLUMN()-COLUMN($C$12), ROW()-ROW($C$12))), "", _xlfn.XLOOKUP(OFFSET($C$12, COLUMN()-COLUMN($C$12), ROW()-ROW($C$12)), Sheet7!$A$2:$A$8, Sheet7!$B$2:$B$8, "")) -> Moderately More Important | O30: =IF(ISBLANK(OFFSET($C$12, COLUMN()-COLUMN($C$12), ROW()-ROW($C$12))), "", _xlfn.XLOOKUP(OFFSET($C$12, COLUMN()-COLUMN($C$12), ROW()-ROW($C$12)), Sheet7!$A$2:$A$8, Sheet7!$B$2:$B$8, "")) -> Moderately More Important | P30: =IF(ISBLANK(OFFSET($C$12, COLUMN()-COLUMN($C$12), ROW()-ROW($C$12))), "", _xlfn.XLOOKUP(OFFSET($C$12, COLUMN()-COLUMN($C$12), ROW()-ROW($C$12)), Sheet7!$A$2:$A$8, Sheet7!$B$2:$B$8, "")) -> Moderately More Important | Q30: =IF(ISBLANK(OFFSET($C$12, COLUMN()-COLUMN($C$12), ROW()-ROW($C$12))), "", _xlfn.XLOOKUP(OFFSET($C$12, COLUMN()-COLUMN($C$12), ROW()-ROW($C$12)), Sheet7!$A$2:$A$8, Sheet7!$B$2:$B$8, "")) -> Moderately More Important | R30: =IF(ISBLANK(OFFSET($C$12, COLUMN()-COLUMN($C$12), ROW()-ROW($C$12))), "", _xlfn.XLOOKUP(OFFSET($C$12, COLUMN()-COLUMN($C$12), ROW()-ROW($C$12)), Sheet7!$A$2:$A$8, Sheet7!$B$2:$B$8, "")) -> Strongly More Important | S30: =IF(ISBLANK(OFFSET($C$12, COLUMN()-COLUMN($C$12), ROW()-ROW($C$12))), "", _xlfn.XLOOKUP(OFFSET($C$12, COLUMN()-COLUMN($C$12), ROW()-ROW($C$12)), Sheet7!$A$2:$A$8, Sheet7!$B$2:$B$8, "")) -> Equal Importance | T30: =IF(ISBLANK(OFFSET($C$12, COLUMN()-COLUMN($C$12), ROW()-ROW($C$12))), "", _xlfn.XLOOKUP(OFFSET($C$12, COLUMN()-COLUMN($C$12), ROW()-ROW($C$12)), Sheet7!$A$2:$A$8, Sheet7!$B$2:$B$8, "")) -> Equal Importance | U30: Equal Importance | V30: Moderately More Important | W30: Slightly Less Important | X30: Strongly More Important | Y30: Strongly More Important | Z30: Slightly Less Important
A31: P21 | B31: =IF(ISBLANK(OFFSET($C$12, COLUMN()-COLUMN($C$12), ROW()-ROW($C$12))), "", _xlfn.XLOOKUP(OFFSET($C$12, COLUMN()-COLUMN($C$12), ROW()-ROW($C$12)), Sheet7!A2:A8, Sheet7!B2:B8, "")) -> Strongly More Important | C31: =IF(ISBLANK(OFFSET($C$12, COLUMN()-COLUMN($C$12), ROW()-ROW($C$12))), "", _xlfn.XLOOKUP(OFFSET($C$12, COLUMN()-COLUMN($C$12), ROW()-ROW($C$12)), Sheet7!A2:A8, Sheet7!B2:B8, "")) -> Moderately More Important | D31: =IF(ISBLANK(OFFSET($C$12, COLUMN()-COLUMN($C$12), ROW()-ROW($C$12))), "", _xlfn.XLOOKUP(OFFSET($C$12, COLUMN()-COLUMN($C$12), ROW()-ROW($C$12)), Sheet7!A2:A8, Sheet7!B2:B8, "")) -> Moderately Less Important | E31: =IF(ISBLANK(OFFSET($C$12, COLUMN()-COLUMN($C$12), ROW()-ROW($C$12))), "", _xlfn.XLOOKUP(OFFSET($C$12, COLUMN()-COLUMN($C$12), ROW()-ROW($C$12)), Sheet7!A2:A8, Sheet7!B2:B8, "")) -> Moderately Less Important | F31: =IF(ISBLANK(OFFSET($C$12, COLUMN()-COLUMN($C$12), ROW()-ROW($C$12))), "", _xlfn.XLOOKUP(OFFSET($C$12, COLUMN()-COLUMN($C$12), ROW()-ROW($C$12)), Sheet7!A2:A8, Sheet7!B2:B8, "")) -> Moderately Less Important | G31: =IF(ISBLANK(OFFSET($C$12, COLUMN()-COLUMN($C$12), ROW()-ROW($C$12))), "", _xlfn.XLOOKUP(OFFSET($C$12, COLUMN()-COLUMN($C$12), ROW()-ROW($C$12)), Sheet7!A2:A8, Sheet7!B2:B8, "")) -> Moderately Less Important | H31: =IF(ISBLANK(OFFSET($C$12, COLUMN()-COLUMN($C$12), ROW()-ROW($C$12))), "", _xlfn.XLOOKUP(OFFSET($C$12, COLUMN()-COLUMN($C$12), ROW()-ROW($C$12)), Sheet7!A2:A8, Sheet7!B2:B8, "")) -> Moderately Less Important | I31: =IF(ISBLANK(OFFSET($C$12, COLUMN()-COLUMN($C$12), ROW()-ROW($C$12))), "", _xlfn.XLOOKUP(OFFSET($C$12, COLUMN()-COLUMN($C$12), ROW()-ROW($C$12)), Sheet7!A2:A8, Sheet7!B2:B8, "")) -> Slightly More Important | J31: =IF(ISBLANK(OFFSET($C$12, COLUMN()-COLUMN($C$12), ROW()-ROW($C$12))), "", _xlfn.XLOOKUP(OFFSET($C$12, COLUMN()-COLUMN($C$12), ROW()-ROW($C$12)), Sheet7!A2:A8, Sheet7!B2:B8, "")) -> Slightly More Important | K31: =IF(ISBLANK(OFFSET($C$12, COLUMN()-COLUMN($C$12), ROW()-ROW($C$12))), "", _xlfn.XLOOKUP(OFFSET($C$12, COLUMN()-COLUMN($C$12), ROW()-ROW($C$12)), Sheet7!A2:A8, Sheet7!B2:B8, "")) -> Strongly More Important | L31: =IF(ISBLANK(OFFSET($C$12, COLUMN()-COLUMN($C$12), ROW()-ROW($C$12))), "", _xlfn.XLOOKUP(OFFSET($C$12, COLUMN()-COLUMN($C$12), ROW()-ROW($C$12)), Sheet7!A2:A8, Sheet7!B2:B8, "")) -> Slightly Less Important | M31: =IF(ISBLANK(OFFSET($C$12, COLUMN()-COLUMN($C$12), ROW()-ROW($C$12))), "", _xlfn.XLOOKUP(OFFSET($C$12, COLUMN()-COLUMN($C$12), ROW()-ROW($C$12)), Sheet7!$A$2:$A$8, Sheet7!$B$2:$B$8, "")) -> Moderately More Important | N31: =IF(ISBLANK(OFFSET($C$12, COLUMN()-COLUMN($C$12), ROW()-ROW($C$12))), "", _xlfn.XLOOKUP(OFFSET($C$12, COLUMN()-COLUMN($C$12), ROW()-ROW($C$12)), Sheet7!$A$2:$A$8, Sheet7!$B$2:$B$8, "")) -> Moderately More Important | O31: =IF(ISBLANK(OFFSET($C$12, COLUMN()-COLUMN($C$12), ROW()-ROW($C$12))), "", _xlfn.XLOOKUP(OFFSET($C$12, COLUMN()-COLUMN($C$12), ROW()-ROW($C$12)), Sheet7!$A$2:$A$8, Sheet7!$B$2:$B$8, "")) -> Moderately More Important | P31: =IF(ISBLANK(OFFSET($C$12, COLUMN()-COLUMN($C$12), ROW()-ROW($C$12))), "", _xlfn.XLOOKUP(OFFSET($C$12, COLUMN()-COLUMN($C$12), ROW()-ROW($C$12)), Sheet7!A2:A8, Sheet7!B2:B8, "")) -> Moderately More Important | Q31: =IF(ISBLANK(OFFSET($C$12, COLUMN()-COLUMN($C$12), ROW()-ROW($C$12))), "", _xlfn.XLOOKUP(OFFSET($C$12, COLUMN()-COLUMN($C$12), ROW()-ROW($C$12)), Sheet7!A2:A8, Sheet7!B2:B8, "")) -> Slightly Less Important | R31: =IF(ISBLANK(OFFSET($C$12, COLUMN()-COLUMN($C$12), ROW()-ROW($C$12))), "", _xlfn.XLOOKUP(OFFSET($C$12, COLUMN()-COLUMN($C$12), ROW()-ROW($C$12)), Sheet7!A2:A8, Sheet7!B2:B8, "")) -> Moderately More Important | S31: =IF(ISBLANK(OFFSET($C$12, COLUMN()-COLUMN($C$12), ROW()-ROW($C$12))), "", _xlfn.XLOOKUP(OFFSET($C$12, COLUMN()-COLUMN($C$12), ROW()-ROW($C$12)), Sheet7!$A$2:$A$8, Sheet7!$B$2:$B$8, "")) -> Moderately Less Important | T31: =IF(ISBLANK(OFFSET($C$12, COLUMN()-COLUMN($C$12), ROW()-ROW($C$12))), "", _xlfn.XLOOKUP(OFFSET($C$12, COLUMN()-COLUMN($C$12), ROW()-ROW($C$12)), Sheet7!$A$2:$A$8, Sheet7!$B$2:$B$8, "")) -> Moderately Less Important | U31: =IF(ISBLANK(OFFSET($C$12, COLUMN()-COLUMN($C$12), ROW()-ROW($C$12))), "", _xlfn.XLOOKUP(OFFSET($C$12, COLUMN()-COLUMN($C$12), ROW()-ROW($C$12)), Sheet7!A2:A8, Sheet7!B2:B8, "")) -> Moderately Less Important | V31: Equal Importance | W31: Moderately Less Important | X31: Moderately More Important | Y31: Strongly More Important | Z31: Slightly Less Important
